Workbook

Sheet Assumptions
A1: Grassmere Business Park — All-Scenarios Proforma
A2: 648 & 650 Grassmere Park Drive, Nashville, TN 37211
A3: Blue cells = adjustable inputs | Black cells = formulas | Green cells = cross-sheet links
A5: SUBJECT PROPERTY
A6: Total Site Area (acres) | B6: 23.49 | C6: Total Site Area (SF) | D6: =B6*43560 -> 1023224.4
A7: Main Building (SF) | B7: 162550 | C7: Annex Building (SF) | D7: 61649
A8: Total Building Area (SF) | B8: =B7+D7 -> 224199 | C8: Year Built | D8: 1985
A9: Surface Parking Spaces | B9: 1205 | C9: Parking Ratio (per 1,000 SF) | D9: =B9/(B8/1000) -> 5.3746894
A10: Current Appraised Value | B10: 37400600 | C10: Appraised $/SF | D10: =B10/B9 -> 31037.842
A11: Land Appraised Value | B11: 17394800 | C11: Land Value $/Acre | D11: =B11/B6 -> 740519.37
A12: Acquisition Price (2015) | B12: 25938000 | C12: Acquisition $/SF | D12: =B12/B11 -> 1.4911353
A13: Zoning | B13: IWD | C13: Generator Capacity (kW) | D13: 2250
A14: CC&R Expiration | B14: February 18, 2033 | C14: CC&R Book/Page | D14: Book 6008, Page 866
A16: CAPITAL STRUCTURE
A17: Existing Loan Balance (est.) | B17: 25938000 | C17: Source: Interest-only, no principal paydown
A18: Interest Rate (est.) | B18: 0.065 | C18: Annual Debt Service | D18: =B17*B18 -> 1685970
A19: Loan Maturity | B19: December 2029 | C19: Monthly Debt Service | D19: =D18/12 -> 140497.5
A20: Asurion Annex Lease Expiration | B20: March 2027 | C20: Asurion Annual Rent (est.) | D20: 1047633
A22: SCENARIO 1: SELL AS-IS
A23: Low Sale Price ($/SF) | B23: 65 | C23: Low Total Sale Price | D23: =B23*B8 -> 14572935
A24: Base Sale Price ($/SF) | B24: 85 | C24: Base Total Sale Price | D24: =B24*B8 -> 19056915
A25: High Sale Price ($/SF) | B25: 110 | C25: High Total Sale Price | D25: =B25*B8 -> 24661890
A26: Selling Costs (% of sale price) | B26: 0.02 | C26: Source: Broker commissions + legal
A27: Months to Close | B27: 6 | C27: Carry Cost During Marketing | D27: =(B18*B17)/12*B27 -> 842985
A28: Buyer Cap Rate (on Asurion income) | B28: 0.085 | C28: Implied Value (Income Approach) | D28: =D20/B28 -> 12325094
A30: SCENARIO 2: RE-LEASE MAIN BUILDING
A31: Leasable Area (Main Bldg SF) | B31: 162550 | C31: Market Rent ($/SF Full Service) | D31: 18
A32: Lease-Up Period (months) | B32: 24 | C32: Annual Rent Escalation | D32: 0.025
A33: Stabilized Occupancy | B33: 0.8 | C33: Exit Cap Rate | D33: 0.085
A34: TI Allowance ($/SF) | B34: 40 | C34: Total TI Cost | D34: =B34*B31 -> 6502000
A35: Leasing Commission (%) | B35: 0.06 | C35: Capital Improvements (deferred maint.) | D35: 3000000
A36: OpEx ($/SF Full Service) | B36: 12 | C36: OpEx Escalation | D36: 0.03
A37: Management Fee (% of EGI) | B37: 0.04
A39: SCENARIO 3: REDEVELOP — SEE EXISTING PROFORMA
A40: Demolition Cost ($/SF) | B40: 12 | C40: Total Demolition Cost | D40: =B40*B8 -> 2690388
A41: Abatement/Environmental (est.) | B41: 500000 | C41: Site Prep / Grading | D41: 750000
A42: Total Demo + Site Prep | D42: =D40+B41+D41 -> 3940388
A44: GENERAL ASSUMPTIONS
A45: Discount Rate (WACC) | B45: 0.09
A46: Analysis Period | B46: 2026-2032 (7 years)
...

Sheet 1 - Sell As-Is
A1: Scenario 1: Sell Property As-Is
A2: 648 & 650 Grassmere Park Drive
B4: Low Case | C4: Base Case | D4: High Case
A5: SALE PROCEEDS
A6: Sale Price ($/SF) | B6: =Assumptions!B23 -> 65 | C6: =Assumptions!B24 -> 85 | D6: =Assumptions!B25 -> 110
A7: Gross Sale Price | B7: =B6*Assumptions!B8 -> 14572935 | C7: =C6*Assumptions!B8 -> 19056915 | D7: =D6*Assumptions!B8 -> 24661890
A8: Less: Selling Costs (2%) | B8: =-B7*Assumptions!B49 -> -291458.7 | C8: =-C7*Assumptions!B49 -> -381138.3 | D8: =-D7*Assumptions!B49 -> -493237.8
A9: Less: Carry Cost (6 mo. debt service) | B9: =-Assumptions!D18/12*Assumptions!B27 -> -842985 | C9: =-Assumptions!D18/12*Assumptions!B27 -> -842985 | D9: =-Assumptions!D18/12*Assumptions!B27 -> -842985
A10: Net Sale Proceeds | B10: =SUM(B7:B9) -> 13438491 | C10: =SUM(C7:C9) -> 17832792 | D10: =SUM(D7:D9) -> 23325667
A12: DEBT RETIREMENT
A13: Existing Loan Balance | B13: =Assumptions!B17 -> 25938000 | C13: =Assumptions!B17 -> 25938000 | D13: =Assumptions!B17 -> 25938000
A14: Net Proceeds Less Debt | B14: =B10-B13 -> -12499509 | C14: =C10-C13 -> -8105208.3 | D14: =D10-D13 -> -2612332.8
A15: Shortfall / Surplus | B15: =IF(B14>=0,"SURPLUS","SHORTFALL: "&TEXT(-B14,"$#,##0")) -> SHORTFALL: $12,499,509 | C15: =IF(C14>=0,"SURPLUS","SHORTFALL: "&TEXT(-C14,"$#,##0")) -> SHORTFALL: $8,105,208 | D15: =IF(D14>=0,"SURPLUS","SHORTFALL: "&TEXT(-D14,"$#,##0")) -> SHORTFALL: $2,612,333
A17: COMPARABLE SALES EVIDENCE
A18: Comparable | B18: $/SF | C18: Year / SF / Notes
A19: 100 Centerview Dr (138551) | B19: 78 | C19: 2025 | 248,573 SF | 1984 | 25.4 ac | Suburban
A20: 5244 Hickory Hollow (283416) | B20: 117 | C20: 2022 | 170,750 SF | 1978 | 17.7 ac | Suburban
A21: 41 Rachel Dr (170790) | B21: 70 | C21: 2025 | 157,262 SF | 1992 | 13.5 ac | Suburban
A22: 1 Burton Hills Blvd (210667) | B22: 98 | C22: 2025 | 121,968 SF | 1985 | 7.1 ac | Suburban
A23: 400 Deaderick St (129061) | B23: 54 | C23: 2025 | 295,914 SF | 1985 | Downtown distressed
A24: 636 Grassmere Park (215185) | B24: 236 | C24: 2022 | 63,474 SF | 1985 | NEIGHBOR (occupied)
A25: 424 Church St (130803) | B25: 85 | C25: 2025 | 647,732 SF | 1985 | Downtown
A26: 1321 Murfreesboro Pk (302467) | B26: 97 | C26: 2021 | 189,836 SF | 1987 | South Nash corridor
A28: SUBJECT PROPERTY DISCOUNT FACTORS:
A29: 73% vacant (main bldg empty since 2022)
A30: Asurion lease expires Mar 2027 (no renewal)
A31: Single access point (Trousdale Dr only)
A32: CC&Rs restrict uses until Feb 2033
A33: Loan maturity Dec 2029 creates urgency

Sheet 2 - Re-Lease
A1: Scenario 2: Re-Lease Main Building
A2: 648 & 650 Grassmere Park Drive
B4: Year 0 2026 | C4: Year 1 2027 | D4: Year 2 2028 | E4: Year 3 2029 | F4: Year 4 2030 | G4: Year 5 2031 | H4: Year 6 2032 | I4: Total/Exit
A5: CAPITAL EXPENDITURES (UPFRONT)
A6: Capital Improvements (Deferred Maint.) | B6: =Assumptions!D35 -> 3000000
A7: Tenant Improvements | B7: =-Assumptions!D35 -> -3000000
A8: Leasing Commissions | B8: =-Assumptions!D34 -> -6502000 | C8: =Assumptions!B35*Assumptions!D31*Assumptions!B31*5 -> 877770
A9: TOTAL CAPITAL EXPENDITURE | B9: 0 | C9: =-Assumptions!B35*Assumptions!D31*Assumptions!B31*5 -> -877770 | D9: =SUM(D6:D8) -> 0 | E9: =SUM(E6:E8) -> 0 | F9: =SUM(F6:F8) -> 0 | G9: =SUM(G6:G8) -> 0 | H9: =SUM(H6:H8) -> 0 | I9: =SUM(I6:I8) -> 0
A11: REVENUE
A12: Asurion Annex Rent | B12: =Assumptions!D20 -> 1047633 | C12: =Assumptions!D20*0.25 -> 261908.25 | D12: 0 | E12: 0 | F12: 0 | G12: 0 | H12: 0
A13: Main Bldg Gross Potential Rent | B13: 0 | C13: =Assumptions!D31*Assumptions!B31*0.25 -> 731475 | D13: =Assumptions!D31*Assumptions!B31*0.6*(1+Assumptions!D32) -> 1799428.5 | E13: =Assumptions!D31*Assumptions!B31*Assumptions!B33*(1+Assumptions!D32)^2 -> 2459219 | F13: =Assumptions!D31*Assumptions!B31*Assumptions!B33*(1+Assumptions!D32)^3 -> 2520699.4 | G13: =Assumptions!D31*Assumptions!B31*Assumptions!B33*(1+Assumptions!D32)^4 -> 2583716.9 | H13: =Assumptions!D31*Assumptions!B31*Assumptions!B33*(1+Assumptions!D32)^5 -> 2648309.8
A14: Vacancy Loss | B14: 0 | C14: 0 | D14: 0 | E14: 0 | F14: 0 | G14: 0 | H14: 0
A15: EFFECTIVE GROSS INCOME | B15: =SUM(B12:B14) -> 1047633 | C15: =SUM(C12:C14) -> 993383.25 | D15: =SUM(D12:D14) -> 1799428.5 | E15: =SUM(E12:E14) -> 2459219 | F15: =SUM(F12:F14) -> 2520699.4 | G15: =SUM(G12:G14) -> 2583716.9 | H15: =SUM(H12:H14) -> 2648309.8 | I15: =SUM(I12:I14) -> 0
A17: OPERATING EXPENSES
A18: Property Taxes | B18: =Assumptions!B47*Assumptions!B10 -> 1028516.5 | C18: =Assumptions!B47*Assumptions!B10 -> 1028516.5 | D18: =Assumptions!B47*Assumptions!B10 -> 1028516.5 | E18: =Assumptions!B47*Assumptions!B10 -> 1028516.5 | F18: =Assumptions!B47*Assumptions!B10 -> 1028516.5 | G18: =Assumptions!B47*Assumptions!B10 -> 1028516.5 | H18: =Assumptions!B47*Assumptions!B10 -> 1028516.5
A19: Insurance | B19: =Assumptions!B48*Assumptions!B8 -> 336298.5 | C19: =Assumptions!B48*Assumptions!B8 -> 336298.5 | D19: =Assumptions!B48*Assumptions!B8 -> 336298.5 | E19: =Assumptions!B48*Assumptions!B8 -> 336298.5 | F19: =Assumptions!B48*Assumptions!B8 -> 336298.5 | G19: =Assumptions!B48*Assumptions!B8 -> 336298.5 | H19: =Assumptions!B48*Assumptions!B8 -> 336298.5
A20: Operating Expenses (Full Service) | B20: =Assumptions!B36*Assumptions!D7 -> 739788 | C20: =Assumptions!B36*Assumptions!B8 -> 2690388 | D20: =Assumptions!B36*Assumptions!B8*(1+Assumptions!D36)^1 -> 2771099.6 | E20: =Assumptions!B36*Assumptions!B8*(1+Assumptions!D36)^2 -> 2854232.6 | F20: =Assumptions!B36*Assumptions!B8*(1+Assumptions!D36)^3 -> 2939859.6 | G20: =Assumptions!B36*Assumptions!B8*(1+Assumptions!D36)^4 -> 3028055.4 | H20: =Assumptions!B36*Assumptions!B8*(1+Assumptions!D36)^5 -> 3118897.1
A21: Management Fee (% of EGI) | B21: =Assumptions!B37*MAX(B15,0) -> 41905.32 | C21: =Assumptions!B37*MAX(C15,0) -> 39735.33 | D21: =Assumptions!B37*MAX(D15,0) -> 71977.14 | E21: =Assumptions!B37*MAX(E15,0) -> 98368.758 | F21: =Assumptions!B37*MAX(F15,0) -> 100827.98 | G21: =Assumptions!B37*MAX(G15,0) -> 103348.68 | H21: =Assumptions!B37*MAX(H15,0) -> 105932.39
A22: TOTAL OPERATING EXPENSES | B22: =SUM(B18:B21) -> 2146508.3 | C22: =SUM(C18:C21) -> 4094938.3 | D22: =SUM(D18:D21) -> 4207891.8 | E22: =SUM(E18:E21) -> 4317416.4 | F22: =SUM(F18:F21) -> 4405502.6 | G22: =SUM(G18:G21) -> 4496219.1 | H22: =SUM(H18:H21) -> 4589644.5 | I22: =SUM(I18:I21) -> 0
A24: NET OPERATING INCOME
A25: NET OPERATING INCOME (NOI) | B25: =B15-B22 -> -1098875.3 | C25: =C15-C22 -> -3101555.1 | D25: =D15-D22 -> -2408463.3 | E25: =E15-E22 -> -1858197.4 | F25: =F15-F22 -> -1884803.2 | G25: =G15-G22 -> -1912502.2 | H25: =H15-H22 -> -1941334.6
A27: DEBT SERVICE
A28: Annual Debt Service | B28: =-Assumptions!D18 -> -1685970 | C28: =-Assumptions!D18 -> -1685970 | D28: =-Assumptions!D18 -> -1685970 | E28: =-Assumptions!D18 -> -1685970 | F28: =-Assumptions!D18 -> -1685970 | G28: =-Assumptions!D18 -> -1685970 | H28: =-Assumptions!D18 -> -1685970
A29: CASH FLOW AFTER DEBT SERVICE | B29: =B25+B28+B9 -> -2784845.3 | C29: =C25+C28+C9 -> -5665295.1 | D29: =D25+D28+D9 -> -4094433.3 | E29: =E25+E28+E9 -> -3544167.4 | F29: =F25+F28+F9 -> -3570773.2 | G29: =G25+G28+G9 -> -3598472.2 | H29: =H25+H28+H9 -> -3627304.6
A31: EXIT / REVERSION (Year 6 - 2032)
A32: Year 6 NOI (Stabilized) | B32: =H25 -> -1941334.6
A33: Exit Cap Rate | B33: =Assumptions!D33 -> 0.085
A34: Gross Sale Price | B34: =IF(B32>0,B32/B33,0) -> 0 | C34: NOI negative — no viable exit at stabilization
A35: Less: Selling Costs | B35: =-B34*Assumptions!B49 -> 0
A36: Less: Loan Payoff | B36: =-Assumptions!B17 -> -25938000
A37: NET EQUITY REVERSION | B37: =IF(B34>0,B34+B35+B36,B36) -> -25938000
A39: RETURN METRICS
A40: Total Capital Invested | B40: =-I9 -> 0
A41: Stabilized Yield on Cost | B41: =IF(B40=0,0,B34/B40) -> 0
A42: Unlevered IRR | B42: Calculate manually
A43: Multiple on Equity

Sheet Scenario Comparison
A1: Scenario Comparison Matrix
A2: 648 & 650 Grassmere Park Drive
A4: Metric | B4: 1: Sell As-Is | C4: 2: Re-Lease | D4: 3A: Warehouse | E4: 3B: Flex Industrial | F4: 3C: Data Center | G4: 3D: Multifamily
A5: Total Capital Required | B5: Selling costs only (~$400K) | C5: ~$12.5M upfront | D5: N/A | E5: N/A | F5: N/A | G5: N/A
A6: Timeline to Revenue | B6: 6 months | C6: 24-36 months | D6: 14+ months | E6: 8 months | F6: 12 months | G6: 32+ months
A7: IWD Permitted by Right | B7: Yes (sale) | C7: Yes | D7: Yes | E7: Yes | F7: Yes | G7: No (SE Required)
A8: CC&R Compliant (pre-2033) | B8: Yes | C8: Yes | D8: Yes | E8: Yes | F8: Yes | G8: No (residential)
A9: Preserves Asurion Income | B9: Yes (through close) | C9: Yes (through Mar 2027) | D9: No | E9: Yes | F9: Yes | G9: No
A10: Stabilized NOI
A11: Exit Value (Gross)
A12: Net Equity After Debt
A13: Yield on Cost
A14: Covers Loan Balance
A15: Entitlement Risk
A16: Construction Risk
A17: Market/Leasing Risk
A18: Key Advantage
A19: Key Risk

Sheet Sensitivity Analysis
A1: Sensitivity Analysis
A2: Scenario 1: Sell As-Is — Sale Price vs. Debt Coverage
A4: Sale Price ($/SF) | B4: Gross Proceeds | C4: Net Proceeds | D4: Less Debt ($25.9M) | E4: Surplus / (Shortfall)
A5: 50 | B5: =A5*Assumptions!B8 -> 11209950 | C5: =B5*(1-Assumptions!B49)-Assumptions!D18/12*6 -> 10142766 | D5: =-Assumptions!B17 -> -25938000 | E5: =C5+D5 -> -15795234
A6: 60 | B6: =A6*Assumptions!B8 -> 13451940 | C6: =B6*(1-Assumptions!B49)-Assumptions!D18/12*6 -> 12339916 | D6: =-Assumptions!B17 -> -25938000 | E6: =C6+D6 -> -13598084
A7: 70 | B7: =A7*Assumptions!B8 -> 15693930 | C7: =B7*(1-Assumptions!B49)-Assumptions!D18/12*6 -> 14537066 | D7: =-Assumptions!B17 -> -25938000 | E7: =C7+D7 -> -11400934
A8: 80 | B8: =A8*Assumptions!B8 -> 17935920 | C8: =B8*(1-Assumptions!B49)-Assumptions!D18/12*6 -> 16734217 | D8: =-Assumptions!B17 -> -25938000 | E8: =C8+D8 -> -9203783.4
A9: 85 | B9: =A9*Assumptions!B8 -> 19056915 | C9: =B9*(1-Assumptions!B49)-Assumptions!D18/12*6 -> 17832792 | D9: =-Assumptions!B17 -> -25938000 | E9: =C9+D9 -> -8105208.3
A10: 90 | B10: =A10*Assumptions!B8 -> 20177910 | C10: =B10*(1-Assumptions!B49)-Assumptions!D18/12*6 -> 18931367 | D10: =-Assumptions!B17 -> -25938000 | E10: =C10+D10 -> -7006633.2
A11: 100 | B11: =A11*Assumptions!B8 -> 22419900 | C11: =B11*(1-Assumptions!B49)-Assumptions!D18/12*6 -> 21128517 | D11: =-Assumptions!B17 -> -25938000 | E11: =C11+D11 -> -4809483
A12: 110 | B12: =A12*Assumptions!B8 -> 24661890 | C12: =B12*(1-Assumptions!B49)-Assumptions!D18/12*6 -> 23325667 | D12: =-Assumptions!B17 -> -25938000 | E12: =C12+D12 -> -2612332.8
A13: 116 | B13: =A13*Assumptions!B8 -> 26007084 | C13: =B13*(1-Assumptions!B49)-Assumptions!D18/12*6 -> 24643957 | D13: =-Assumptions!B17 -> -25938000 | E13: =C13+D13 -> -1294042.7
A14: 120 | B14: =A14*Assumptions!B8 -> 26903880 | C14: =B14*(1-Assumptions!B49)-Assumptions!D18/12*6 -> 25522817 | D14: =-Assumptions!B17 -> -25938000 | E14: =C14+D14 -> -415182.6
A15: 130 | B15: =A15*Assumptions!B8 -> 29145870 | C15: =B15*(1-Assumptions!B49)-Assumptions!D18/12*6 -> 27719968 | D15: =-Assumptions!B17 -> -25938000 | E15: =C15+D15 -> 1781967.6
A16: 140 | B16: =A16*Assumptions!B8 -> 31387860 | C16: =B16*(1-Assumptions!B49)-Assumptions!D18/12*6 -> 29917118 | D16: =-Assumptions!B17 -> -25938000 | E16: =C16+D16 -> 3979117.8
A17: 150 | B17: =A17*Assumptions!B8 -> 33629850 | C17: =B17*(1-Assumptions!B49)-Assumptions!D18/12*6 -> 32114268 | D17: =-Assumptions!B17 -> -25938000 | E17: =C17+D17 -> 6176268
A20: Scenario 2: Re-Lease — Rent/SF vs. Stabilized NOI
A22: Rent ($/SF FS) | B22: Gross Revenue | C22: OpEx | D22: Stabilized NOI | E22: NOI / Debt Service
A23: 14 | B23: =A23*Assumptions!B8*Assumptions!B33 -> 2511028.8 | C23: =-Assumptions!B36*Assumptions!B8 -> -2690388 | D23: =B23+C23 -> -179359.2 | E23: =IF(Assumptions!D18=0,0,D23/Assumptions!D18) -> -0.10638339
A24: 16 | B24: =A24*Assumptions!B8*Assumptions!B33 -> 2869747.2 | C24: =-Assumptions!B36*Assumptions!B8 -> -2690388 | D24: =B24+C24 -> 179359.2 | E24: =IF(Assumptions!D18=0,0,D24/Assumptions!D18) -> 0.10638339
A25: 18 | B25: =A25*Assumptions!B8*Assumptions!B33 -> 3228465.6 | C25: =-Assumptions!B36*Assumptions!B8 -> -2690388 | D25: =B25+C25 -> 538077.6 | E25: =IF(Assumptions!D18=0,0,D25/Assumptions!D18) -> 0.31915016
A26: 20 | B26: =A26*Assumptions!B8*Assumptions!B33 -> 3587184 | C26: =-Assumptions!B36*Assumptions!B8 -> -2690388 | D26: =B26+C26 -> 896796 | E26: =IF(Assumptions!D18=0,0,D26/Assumptions!D18) -> 0.53191694
A27: 22 | B27: =A27*Assumptions!B8*Assumptions!B33 -> 3945902.4 | C27: =-Assumptions!B36*Assumptions!B8 -> -2690388 | D27: =B27+C27 -> 1255514.4 | E27: =IF(Assumptions!D18=0,0,D27/Assumptions!D18) -> 0.74468371
A28: 24 | B28: =A28*Assumptions!B8*Assumptions!B33 -> 4304620.8 | C28: =-Assumptions!B36*Assumptions!B8 -> -2690388 | D28: =B28+C28 -> 1614232.8 | E28: =IF(Assumptions!D18=0,0,D28/Assumptions!D18) -> 0.95745049
A29: 26 | B29: =A29*Assumptions!B8*Assumptions!B33 -> 4663339.2 | C29: =-Assumptions!B36*Assumptions!B8 -> -2690388 | D29: =B29+C29 -> 1972951.2 | E29: =IF(Assumptions!D18=0,0,D29/Assumptions!D18) -> 1.1702173
A32: Scenario 2: Exit Cap Rate Sensitivity
A34: Exit Cap Rate | B34: Stabilized NOI ($18/SF) | C34: Implied Value | D34: Less Debt | E34: Net Equity
A35: 0.065 | B35: =Assumptions!D31*Assumptions!B8*Assumptions!B33-Assumptions!B36*Assumptions!B8 -> 538077.6 | C35: =B35/A35 -> 8278116.9 | D35: =-Assumptions!B17 -> -25938000 | E35: =C35*(1-Assumptions!B49)+D35 -> -17825445
A36: 0.07 | B36: =Assumptions!D31*Assumptions!B8*Assumptions!B33-Assumptions!B36*Assumptions!B8 -> 538077.6 | C36: =B36/A36 -> 7686822.9 | D36: =-Assumptions!B17 -> -25938000 | E36: =C36*(1-Assumptions!B49)+D36 -> -18404914
A37: 0.075 | B37: =Assumptions!D31*Assumptions!B8*Assumptions!B33-Assumptions!B36*Assumptions!B8 -> 538077.6 | C37: =B37/A37 -> 7174368 | D37: =-Assumptions!B17 -> -25938000 | E37: =C37*(1-Assumptions!B49)+D37 -> -18907119
A38: 0.08 | B38: =Assumptions!D31*Assumptions!B8*Assumptions!B33-Assumptions!B36*Assumptions!B8 -> 538077.6 | C38: =B38/A38 -> 6725970 | D38: =-Assumptions!B17 -> -25938000 | E38: =C38*(1-Assumptions!B49)+D38 -> -19346549
A39: 0.085 | B39: =Assumptions!D31*Assumptions!B8*Assumptions!B33-Assumptions!B36*Assumptions!B8 -> 538077.6 | C39: =B39/A39 -> 6330324.7 | D39: =-Assumptions!B17 -> -25938000 | E39: =C39*(1-Assumptions!B49)+D39 -> -19734282
A40: 0.09 | B40: =Assumptions!D31*Assumptions!B8*Assumptions!B33-Assumptions!B36*Assumptions!B8 -> 538077.6 | C40: =B40/A40 -> 5978640 | D40: =-Assumptions!B17 -> -25938000 | E40: =C40*(1-Assumptions!B49)+D40 -> -20078933
A41: 0.095 | B41: =Assumptions!D31*Assumptions!B8*Assumptions!B33-Assumptions!B36*Assumptions!B8 -> 538077.6 | C41: =B41/A41 -> 5663974.7 | D41: =-Assumptions!B17 -> -25938000 | E41: =C41*(1-Assumptions!B49)+D41 -> -20387305
A42: 0.1 | B42: =Assumptions!D31*Assumptions!B8*Assumptions!B33-Assumptions!B36*Assumptions!B8 -> 538077.6 | C42: =B42/A42 -> 5380776 | D42: =-Assumptions!B17 -> -25938000 | E42: =C42*(1-Assumptions!B49)+D42 -> -20664840
