Workbook

Sheet Assumptions
A1: Scenario 3: Redevelopment Proforma
A2: 648 & 650 Grassmere Park Drive, Nashville, TN 37211
A3: All blue cells are adjustable inputs
A5: SUBJECT PROPERTY
A6: Total Site Area (acres) | B6: 23.49 | C6: Total Site Area (SF) | D6: =B6*43560 -> 1023224.4
A7: Main Building (SF) | B7: 162550 | C7: Annex Building (SF) | D7: 61649
A8: Total Building Area (SF) | B8: =B7+D7 -> 224199 | C8: Year Built | D8: 1985
A9: Surface Parking Spaces | B9: 1205 | C9: Parking Ratio (per 1,000 SF) | D9: =B9/(B8/1000) -> 5.3746894
A10: Current Appraised Value | B10: 37400600 | C10: Appraised $/SF | D10: =B10/B8 -> 166.81876
A11: Land Appraised Value | B11: 17394800 | C11: Land Value $/Acre | D11: =B11/B6 -> 740519.37
A12: Acquisition Price (2015) | B12: 25938000 | C12: Acquisition $/SF | D12: =B12/B8 -> 115.69186
A13: Zoning | B13: IWD | C13: Generator Capacity (kW) | D13: 2250
A15: CAPITAL STRUCTURE
A16: Existing Loan Balance (est.) | B16: 25938000 | C16: Source: Interest-only, no principal paydown
A17: Interest Rate (est.) | B17: 0.065 | C17: Annual Debt Service | D17: =B16*B17 -> 1685970
A18: Loan Maturity | B18: December 2029 | C18: Monthly Debt Service | D18: =D17/12 -> 140497.5
A19: Asurion Annex Lease Expiration | B19: March 2027 | C19: Asurion Annual Rent (est.) | D19: 1047633
A21: DEMOLITION COSTS
A22: Demolition Cost ($/SF) | B22: 12 | C22: Source: RS Means 2025 Nashville avg for commercial demo
A23: Total Demolition Cost | B23: =B22*B8 -> 2690388 | C23: Abatement/Environmental (est.) | D23: 500000
A24: Site Preparation / Grading | B24: 750000 | C24: Total Demo + Site Prep | D24: =B23+D23+B24 -> 3940388
A26: SCENARIO 3A: WAREHOUSE / DISTRIBUTION
A27: New Building Size (SF) | B27: 350000 | C27: Construction Cost ($/SF) | D27: 95
A28: Total Construction Cost | B28: =B27*D27 -> 33250000 | C28: Lease Rate ($/SF/yr NNN) | D28: 8.5
A29: Stabilized Occupancy | B29: 0.95 | C29: Cap Rate (Exit) | D29: 0.06
A30: Lease-Up Period (months) | B30: 12 | C30: TI Allowance ($/SF) | D30: 5
A31: Leasing Commission (%) | B31: 0.05 | C31: Construction Timeline (months) | D31: 14
A32: Annual OpEx ($/SF) | B32: 2.5 | C32: Annual Rent Escalation | D32: 0.025
A34: SCENARIO 3B: FLEX INDUSTRIAL / BUSINESS CENTER
A35: Conversion Area (SF) - Main Bldg | B35: 162550 | C35: Renovation Cost ($/SF) | D35: 45
A36: Total Renovation Cost | B36: =B35*D35 -> 7314750 | C36: Lease Rate ($/SF/yr Modified Gross) | D36: 14
A37: Stabilized Occupancy | B37: 0.85 | C37: Cap Rate (Exit) | D37: 0.075
A38: Lease-Up Period (months) | B38: 18 | C38: TI Allowance ($/SF) | D38: 20
A39: Leasing Commission (%) | B39: 0.06 | C39: Construction Timeline (months) | D39: 8
A40: Annual OpEx ($/SF) | B40: 6.5 | C40: Annual Rent Escalation | D40: 0.025
A42: SCENARIO 3C: DATA CENTER SHELL
A43: Conversion Area (SF) - Main Bldg | B43: 162550 | C43: Conversion Cost ($/SF) | D43: 150
A44: Total Conversion Cost | B44: =B43*D43 -> 24382500 | C44: Lease Rate ($/SF/yr NNN) | D44: 85
A45: Usable Data Hall (% of total) | B45: 0.6 | C45: Stabilized Occupancy | D45: 0.95
A46: Usable Data Hall SF | B46: =B43*B45 -> 97530 | C46: Cap Rate (Exit) | D46: 0.055
...

Sheet Summary
A1: Scenario 3: Redevelopment Alternatives Comparison
A2: 648 & 650 Grassmere Park Drive, Nashville, TN 37211
A4: Metric | B4: 3A: Warehouse | C4: 3B: Flex Industrial | D4: 3C: Data Center | E4: 3D: Multifamily
A5: Total Development Cost | B5: ='3A Warehouse'!I13 -> 48386735 | C5: ='3B Flex Industrial'!I13 -> 12530980 | D5: ='3C Data Center'!I13 -> 35405795 | E5: ='3D Multifamily'!I13 -> 95075485
A6: Stabilized NOI (Year 6) | B6: ='3A Warehouse'!H29 -> -893648.12 | C6: ='3B Flex Industrial'!H29 -> -1278420.3 | D6: ='3C Data Center'!H29 -> 1647069.2 | E6: ='3D Multifamily'!H29 -> -105193.3
A7: Yield on Cost | B7: ='3A Warehouse'!B50 -> -0.018468866 | C7: ='3B Flex Industrial'!B50 -> -0.10202078 | D7: ='3C Data Center'!B50 -> 0.046519762 | E7: ='3D Multifamily'!B50 -> -0.0011064188
A8: Development Spread | B8: ='3A Warehouse'!B51 -> -0.078468866 | C8: ='3B Flex Industrial'!B51 -> -0.17702078 | D8: ='3C Data Center'!B51 -> -0.008480238 | E8: ='3D Multifamily'!B51 -> -0.051106419
A9: Gross Sale Price | B9: ='3A Warehouse'!I38 -> -14894135 | C9: ='3B Flex Industrial'!I38 -> -17045604 | D9: ='3C Data Center'!I38 -> 29946712 | E9: ='3D Multifamily'!I38 -> -2103866.1
A10: Net Equity Reversion | B10: ='3A Warehouse'!I42 -> -40534253 | C10: ='3B Flex Industrial'!I42 -> -42642691 | D10: ='3C Data Center'!I42 -> 3409777.7 | E10: ='3D Multifamily'!I42 -> -27999789
A11: Profit Over Cost | B11: ='3A Warehouse'!B53 -> -88920988 | C11: ='3B Flex Industrial'!B53 -> -55173671 | D11: ='3C Data Center'!B53 -> -31996017 | E11: ='3D Multifamily'!B53 -> -1.2307527e+08
A12: Multiple on Equity | B12: ='3A Warehouse'!B54 -> -1.1504537 | C12: ='3B Flex Industrial'!B54 -> -4.9367552 | D12: ='3C Data Center'!B54 -> 0.0077164794 | E12: ='3D Multifamily'!B54 -> -0.3984253
A13: Entitlement Risk | B13: ='3A Warehouse'!B56 -> LOW - Permitted by right under IWD | C13: ='3B Flex Industrial'!B56 -> LOW - Permitted by right under IWD | D13: ='3C Data Center'!B56 -> LOW - Permitted by right under IWD | E13: ='3D Multifamily'!B56 -> HIGH - Requires BZA Special Exception
A14: Construction Type | B14: ='3A Warehouse'!B57 -> Ground-up new construction (full demolition) | C14: ='3B Flex Industrial'!B57 -> Adaptive reuse / conversion of existing building | D14: ='3C Data Center'!B57 -> Adaptive reuse / conversion of existing building | E14: ='3D Multifamily'!B57 -> Ground-up new construction (full demolition)
A16: TIMELINE & RISK
A17: Requires Demolition | B17: Yes | C17: No | D17: No | E17: Yes
A18: IWD Permitted by Right | B18: Yes | C18: Yes | D18: Yes | E18: No (SE Required)
A19: Preserves Asurion Income | B19: No | C19: Yes | D19: Yes | E19: No
A20: Leverages Existing Infrastructure | B20: No | C20: Partially | D20: Yes (power + cooling) | E20: No
A21: Revenue Start | B21: Year 2 (2028) | C21: Year 1 (2027) | D21: Year 1 (2027) | E21: Year 3 (2029)
A22: Exit Before Loan Maturity (Dec 2029) | B22: Tight | C22: Feasible | D22: Feasible | E22: No

Sheet 3A Warehouse
A1: Scenario 3A: Warehouse / Distribution
A2: 648 & 650 Grassmere Park Drive
B4: Year 0 2026 | C4: Year 1 2027 | D4: Year 2 2028 | E4: Year 3 2029 | F4: Year 4 2030 | G4: Year 5 2031 | H4: Year 6 2032 | I4: Total/Exit
A6: DEVELOPMENT COSTS
A7: Demolition + Site Prep | B7: =Assumptions!D24 -> 3940388
A8: Hard Construction Cost | B8: =Assumptions!B28 -> 33250000
A9: Soft Costs (% of hard costs) | B9: =(B7+B8)*Assumptions!B68 -> 5578558.2
A10: Contingency (% of hard costs) | B10: =(B7+B8)*Assumptions!B69 -> 3719038.8
A11: Tenant Improvements | B11: =Assumptions!D30*Assumptions!B27 -> 1750000
A12: Leasing Commissions (Year 1) | C12: =Assumptions!B31*Assumptions!D28*Assumptions!B27 -> 148750
A13: TOTAL DEVELOPMENT COST | B13: =SUM(B7:B12) -> 48237985 | C13: =SUM(C7:C12) -> 148750 | I13: =SUM(B13:H13) -> 48386735
A15: REVENUE
A16: Asurion Annex Rent (through Mar 2027) | B16: =Assumptions!D19 -> 1047633 | C16: =Assumptions!D19*0.25 -> 261908.25
A17: Warehouse / Distribution Gross Potential Rent | C17: =Assumptions!D28*Assumptions!B27*0.5 -> 1487500 | D17: =C17*(1+Assumptions!D32) -> 1524687.5 | E17: =D17*(1+Assumptions!D32) -> 1562804.7 | F17: =E17*(1+Assumptions!D32) -> 1601874.8 | G17: =F17*(1+Assumptions!D32) -> 1641921.7 | H17: =G17*(1+Assumptions!D32) -> 1682969.7
A18: Vacancy Loss | C18: =-C17*(1-Assumptions!B29) -> -74375 | D18: =-D17*(1-Assumptions!B29) -> -76234.375 | E18: =-E17*(1-Assumptions!B29) -> -78140.234 | F18: =-F17*(1-Assumptions!B29) -> -80093.74 | G18: =-G17*(1-Assumptions!B29) -> -82096.084 | H18: =-H17*(1-Assumptions!B29) -> -84148.486
A19: EFFECTIVE GROSS INCOME | B19: =SUM(B16:B18) -> 1047633 | C19: =SUM(C16:C18) -> 1675033.2 | D19: =SUM(D16:D18) -> 1448453.1 | E19: =SUM(E16:E18) -> 1484664.5 | F19: =SUM(F16:F18) -> 1521781.1 | G19: =SUM(G16:G18) -> 1559825.6 | H19: =SUM(H16:H18) -> 1598821.2 | I19: =SUM(I16:I18) -> 0
A21: OPERATING EXPENSES
A22: Property Taxes | B22: =Assumptions!B64*Assumptions!B11 -> 478357 | C22: =Assumptions!B64*Assumptions!B11 -> 478357 | D22: =Assumptions!B64*Assumptions!B10 -> 1028516.5 | E22: =Assumptions!B64*Assumptions!B10 -> 1028516.5 | F22: =Assumptions!B64*Assumptions!B10 -> 1028516.5 | G22: =Assumptions!B64*Assumptions!B10 -> 1028516.5 | H22: =Assumptions!B64*Assumptions!B10 -> 1028516.5
A23: Insurance | B23: =0 -> 0 | C23: =0 -> 0 | D23: =Assumptions!B65*Assumptions!B27 -> 525000 | E23: =Assumptions!B65*Assumptions!B27 -> 525000 | F23: =Assumptions!B65*Assumptions!B27 -> 525000 | G23: =Assumptions!B65*Assumptions!B27 -> 525000 | H23: =Assumptions!B65*Assumptions!B27 -> 525000
A24: Operating Expenses | B24: =Assumptions!B32*Assumptions!D7 -> 154122.5 | C24: =0 -> 0 | D24: =Assumptions!B32*Assumptions!B27 -> 875000 | E24: =Assumptions!B32*Assumptions!B27 -> 875000 | F24: =Assumptions!B32*Assumptions!B27 -> 875000 | G24: =Assumptions!B32*Assumptions!B27 -> 875000 | H24: =Assumptions!B32*Assumptions!B27 -> 875000
A25: Management Fee | B25: =Assumptions!B66*MAX(B19,0) -> 41905.32 | C25: =Assumptions!B66*MAX(C19,0) -> 67001.33 | D25: =Assumptions!B66*MAX(D19,0) -> 57938.125 | E25: =Assumptions!B66*MAX(E19,0) -> 59386.578 | F25: =Assumptions!B66*MAX(F19,0) -> 60871.243 | G25: =Assumptions!B66*MAX(G19,0) -> 62393.024 | H25: =Assumptions!B66*MAX(H19,0) -> 63952.849
A26: TOTAL OPERATING EXPENSES | B26: =SUM(B22:B25) -> 674384.82 | C26: =SUM(C22:C25) -> 545358.33 | D26: =SUM(D22:D25) -> 2486454.6 | E26: =SUM(E22:E25) -> 2487903.1 | F26: =SUM(F22:F25) -> 2489387.7 | G26: =SUM(G22:G25) -> 2490909.5 | H26: =SUM(H22:H25) -> 2492469.3
A28: NET OPERATING INCOME
A29: NET OPERATING INCOME (NOI) | B29: =B19-B26 -> 373248.18 | C29: =C19-C26 -> 1129674.9 | D29: =D19-D26 -> -1038001.5 | E29: =E19-E26 -> -1003238.6 | F29: =F19-F26 -> -967606.68 | G29: =G19-G26 -> -931083.93 | H29: =H19-H26 -> -893648.12
A31: DEBT SERVICE
A32: Annual Debt Service | B32: =Assumptions!D17 -> 1685970 | C32: =Assumptions!D17 -> 1685970 | D32: =Assumptions!D17 -> 1685970 | E32: =Assumptions!D17 -> 1685970 | F32: =Assumptions!D17 -> 1685970 | G32: =Assumptions!D17 -> 1685970 | H32: =Assumptions!D17 -> 1685970
A33: CASH FLOW AFTER DEBT SERVICE | B33: =B29-B32 -> -1312721.8 | C33: =C29-C32 -> -556295.08 | D33: =D29-D32 -> -2723971.5 | E33: =E29-E32 -> -2689208.6 | F33: =F29-F32 -> -2653576.7 | G33: =G29-G32 -> -2617053.9 | H33: =H29-H32 -> -2579618.1
A35: EXIT ANALYSIS (Year 6 Sale)
A36: Stabilized NOI (Year 6) | I36: =H29 -> -893648.12
A37: Exit Cap Rate | I37: =Assumptions!D29 -> 0.06
A38: Gross Sale Price | I38: =I36/I37 -> -14894135
A39: Selling Costs | I39: =-I38*Assumptions!B67 -> 297882.71
A40: Net Sale Proceeds | I40: =I38+I39 -> -14596253
A41: Less: Loan Payoff | I41: =-Assumptions!B16 -> -25938000
A42: NET EQUITY REVERSION | I42: =I40+I41 -> -40534253
A44: RETURN METRICS
A45: Total Cash Flow (incl. exit) | B45: =B33-B13 -> -49550707 | C45: =C33-C13 -> -705045.08 | D45: =D33-D13 -> -2723971.5 | E45: =E33-E13 -> -2689208.6 | F45: =F33-F13 -> -2653576.7 | G45: =G33-G13 -> -2617053.9 | H45: =H33-H13 -> -2579618.1 | I45: =H33-H13+I42 -> -43113871
A46: Cumulative Cash Flow | B46: =B45 -> -49550707 | C46: =B46+C45 -> -50255752 | D46: =C46+D45 -> -52979723 | E46: =D46+E45 -> -55668932 | F46: =E46+F45 -> -58322509 | G46: =F46+G45 -> -60939563 | H46: =G46+H45 -> -63519181 | I46: =H46+I45 -> -1.0663305e+08
A48: Total Development Cost | B48: =I13 -> 48386735
A49: Stabilized NOI (Year 6) | B49: =H29 -> -893648.12
...

Sheet 3B Flex Industrial
A1: Scenario 3B: Flex Industrial / Business Center
A2: 648 & 650 Grassmere Park Drive
B4: Year 0 2026 | C4: Year 1 2027 | D4: Year 2 2028 | E4: Year 3 2029 | F4: Year 4 2030 | G4: Year 5 2031 | H4: Year 6 2032 | I4: Total/Exit
A6: DEVELOPMENT COSTS
A7: Renovation/Conversion Cost | B7: =Assumptions!B36 -> 7314750
A8: Additional Capital (Power/Infrastructure) | B8: 0
A9: Soft Costs (% of hard costs) | B9: =(B7+B8)*Assumptions!B68 -> 1097212.5
A10: Contingency (% of hard costs) | B10: =(B7+B8)*Assumptions!B69 -> 731475
A11: Tenant Improvements | B11: =Assumptions!D38*Assumptions!B35 -> 3251000
A12: Leasing Commissions (Year 1) | C12: =Assumptions!B39*Assumptions!D36*Assumptions!B35 -> 136542
A13: TOTAL DEVELOPMENT COST | B13: =SUM(B7:B12) -> 12394438 | C13: =SUM(C7:C12) -> 136542 | I13: =SUM(B13:H13) -> 12530980
A15: REVENUE
A16: Asurion Annex Rent (through Mar 2027) | B16: =Assumptions!D19 -> 1047633 | C16: =Assumptions!D19*0.25 -> 261908.25
A17: Flex Industrial / Business Center Gross Potential Rent | C17: =Assumptions!D36*Assumptions!B35*0.5 -> 1137850 | D17: =C17*(1+Assumptions!D40) -> 1166296.2 | E17: =D17*(1+Assumptions!D40) -> 1195453.7 | F17: =E17*(1+Assumptions!D40) -> 1225340 | G17: =F17*(1+Assumptions!D40) -> 1255973.5 | H17: =G17*(1+Assumptions!D40) -> 1287372.8
A18: Vacancy Loss | C18: =-C17*(1-Assumptions!B37) -> -170677.5 | D18: =-D17*(1-Assumptions!B37) -> -174944.44 | E18: =-E17*(1-Assumptions!B37) -> -179318.05 | F18: =-F17*(1-Assumptions!B37) -> -183801 | G18: =-G17*(1-Assumptions!B37) -> -188396.02 | H18: =-H17*(1-Assumptions!B37) -> -193105.93
A19: EFFECTIVE GROSS INCOME | B19: =SUM(B16:B18) -> 1047633 | C19: =SUM(C16:C18) -> 1229080.8 | D19: =SUM(D16:D18) -> 991351.81 | E19: =SUM(E16:E18) -> 1016135.6 | F19: =SUM(F16:F18) -> 1041539 | G19: =SUM(G16:G18) -> 1067577.5 | H19: =SUM(H16:H18) -> 1094266.9 | I19: =SUM(I16:I18) -> 0
A21: OPERATING EXPENSES
A22: Property Taxes | B22: =Assumptions!B64*Assumptions!B11 -> 478357 | C22: =Assumptions!B64*Assumptions!B10 -> 1028516.5 | D22: =Assumptions!B64*Assumptions!B10 -> 1028516.5 | E22: =Assumptions!B64*Assumptions!B10 -> 1028516.5 | F22: =Assumptions!B64*Assumptions!B10 -> 1028516.5 | G22: =Assumptions!B64*Assumptions!B10 -> 1028516.5 | H22: =Assumptions!B64*Assumptions!B10 -> 1028516.5
A23: Insurance | B23: =0 -> 0 | C23: =Assumptions!B65*Assumptions!B35 -> 243825 | D23: =Assumptions!B65*Assumptions!B35 -> 243825 | E23: =Assumptions!B65*Assumptions!B35 -> 243825 | F23: =Assumptions!B65*Assumptions!B35 -> 243825 | G23: =Assumptions!B65*Assumptions!B35 -> 243825 | H23: =Assumptions!B65*Assumptions!B35 -> 243825
A24: Operating Expenses | B24: =Assumptions!B32*Assumptions!D7 -> 154122.5 | C24: =Assumptions!B40*Assumptions!B35 -> 1056575 | D24: =Assumptions!B40*Assumptions!B35 -> 1056575 | E24: =Assumptions!B40*Assumptions!B35 -> 1056575 | F24: =Assumptions!B40*Assumptions!B35 -> 1056575 | G24: =Assumptions!B40*Assumptions!B35 -> 1056575 | H24: =Assumptions!B40*Assumptions!B35 -> 1056575
A25: Management Fee | B25: =Assumptions!B66*MAX(B19,0) -> 41905.32 | C25: =Assumptions!B66*MAX(C19,0) -> 49163.23 | D25: =Assumptions!B66*MAX(D19,0) -> 39654.073 | E25: =Assumptions!B66*MAX(E19,0) -> 40645.424 | F25: =Assumptions!B66*MAX(F19,0) -> 41661.56 | G25: =Assumptions!B66*MAX(G19,0) -> 42703.099 | H25: =Assumptions!B66*MAX(H19,0) -> 43770.676
A26: TOTAL OPERATING EXPENSES | B26: =SUM(B22:B25) -> 674384.82 | C26: =SUM(C22:C25) -> 2378079.7 | D26: =SUM(D22:D25) -> 2368570.6 | E26: =SUM(E22:E25) -> 2369561.9 | F26: =SUM(F22:F25) -> 2370578.1 | G26: =SUM(G22:G25) -> 2371619.6 | H26: =SUM(H22:H25) -> 2372687.2
A28: NET OPERATING INCOME
A29: NET OPERATING INCOME (NOI) | B29: =B19-B26 -> 373248.18 | C29: =C19-C26 -> -1148999 | D29: =D19-D26 -> -1377218.8 | E29: =E19-E26 -> -1353426.3 | F29: =F19-F26 -> -1329039.1 | G29: =G19-G26 -> -1304042.1 | H29: =H19-H26 -> -1278420.3
A31: DEBT SERVICE
A32: Annual Debt Service | B32: =Assumptions!D17 -> 1685970 | C32: =Assumptions!D17 -> 1685970 | D32: =Assumptions!D17 -> 1685970 | E32: =Assumptions!D17 -> 1685970 | F32: =Assumptions!D17 -> 1685970 | G32: =Assumptions!D17 -> 1685970 | H32: =Assumptions!D17 -> 1685970
A33: CASH FLOW AFTER DEBT SERVICE | B33: =B29-B32 -> -1312721.8 | C33: =C29-C32 -> -2834969 | D33: =D29-D32 -> -3063188.8 | E33: =E29-E32 -> -3039396.3 | F33: =F29-F32 -> -3015009.1 | G33: =G29-G32 -> -2990012.1 | H33: =H29-H32 -> -2964390.3
A35: EXIT ANALYSIS (Year 6 Sale)
A36: Stabilized NOI (Year 6) | I36: =H29 -> -1278420.3
A37: Exit Cap Rate | I37: =Assumptions!D37 -> 0.075
A38: Gross Sale Price | I38: =I36/I37 -> -17045604
A39: Selling Costs | I39: =-I38*Assumptions!B67 -> 340912.07
A40: Net Sale Proceeds | I40: =I38+I39 -> -16704691
A41: Less: Loan Payoff | I41: =-Assumptions!B16 -> -25938000
A42: NET EQUITY REVERSION | I42: =I40+I41 -> -42642691
A44: RETURN METRICS
A45: Total Cash Flow (incl. exit) | B45: =B33-B13 -> -13707159 | C45: =C33-C13 -> -2971511 | D45: =D33-D13 -> -3063188.8 | E45: =E33-E13 -> -3039396.3 | F45: =F33-F13 -> -3015009.1 | G45: =G33-G13 -> -2990012.1 | H45: =H33-H13 -> -2964390.3 | I45: =H33-H13+I42 -> -45607082
A46: Cumulative Cash Flow | B46: =B45 -> -13707159 | C46: =B46+C45 -> -16678670 | D46: =C46+D45 -> -19741859 | E46: =D46+E45 -> -22781255 | F46: =E46+F45 -> -25796264 | G46: =F46+G45 -> -28786277 | H46: =G46+H45 -> -31750667 | I46: =H46+I45 -> -77357749
A48: Total Development Cost | B48: =I13 -> 12530980
A49: Stabilized NOI (Year 6) | B49: =H29 -> -1278420.3
...

Sheet 3C Data Center
A1: Scenario 3C: Data Center Shell
A2: 648 & 650 Grassmere Park Drive
B4: Year 0 2026 | C4: Year 1 2027 | D4: Year 2 2028 | E4: Year 3 2029 | F4: Year 4 2030 | G4: Year 5 2031 | H4: Year 6 2032 | I4: Total/Exit
A6: DEVELOPMENT COSTS
A7: Renovation/Conversion Cost | B7: =Assumptions!B44 -> 24382500
A8: Additional Capital (Power/Infrastructure) | B8: =Assumptions!D48 -> 3500000
A9: Soft Costs (% of hard costs) | B9: =(B7+B8)*Assumptions!B68 -> 4182375
A10: Contingency (% of hard costs) | B10: =(B7+B8)*Assumptions!B69 -> 2788250
A11: Tenant Improvements | B11: =Assumptions!D47*Assumptions!B43 -> 0
A12: Leasing Commissions (Year 1) | C12: =Assumptions!B48*Assumptions!D44*Assumptions!B43 -> 552670
A13: TOTAL DEVELOPMENT COST | B13: =SUM(B7:B12) -> 34853125 | C13: =SUM(C7:C12) -> 552670 | I13: =SUM(B13:H13) -> 35405795
A15: REVENUE
A16: Asurion Annex Rent (through Mar 2027) | B16: =Assumptions!D19 -> 1047633 | C16: =Assumptions!D19*0.25 -> 261908.25
A17: Data Center Shell Gross Potential Rent | C17: =Assumptions!D44*Assumptions!B46*0.5 -> 4145025 | D17: =C17*(1+Assumptions!B50) -> 4269375.8 | E17: =D17*(1+Assumptions!B50) -> 4397457 | F17: =E17*(1+Assumptions!B50) -> 4529380.7 | G17: =F17*(1+Assumptions!B50) -> 4665262.2 | H17: =G17*(1+Assumptions!B50) -> 4805220
A18: Vacancy Loss | C18: =-C17*(1-Assumptions!D45) -> -207251.25 | D18: =-D17*(1-Assumptions!D45) -> -213468.79 | E18: =-E17*(1-Assumptions!D45) -> -219872.85 | F18: =-F17*(1-Assumptions!D45) -> -226469.04 | G18: =-G17*(1-Assumptions!D45) -> -233263.11 | H18: =-H17*(1-Assumptions!D45) -> -240261
A19: EFFECTIVE GROSS INCOME | B19: =SUM(B16:B18) -> 1047633 | C19: =SUM(C16:C18) -> 4199682 | D19: =SUM(D16:D18) -> 4055907 | E19: =SUM(E16:E18) -> 4177584.2 | F19: =SUM(F16:F18) -> 4302911.7 | G19: =SUM(G16:G18) -> 4431999 | H19: =SUM(H16:H18) -> 4564959 | I19: =SUM(I16:I18) -> 0
A21: OPERATING EXPENSES
A22: Property Taxes | B22: =Assumptions!B64*Assumptions!B11 -> 478357 | C22: =Assumptions!B64*Assumptions!B10 -> 1028516.5 | D22: =Assumptions!B64*Assumptions!B10 -> 1028516.5 | E22: =Assumptions!B64*Assumptions!B10 -> 1028516.5 | F22: =Assumptions!B64*Assumptions!B10 -> 1028516.5 | G22: =Assumptions!B64*Assumptions!B10 -> 1028516.5 | H22: =Assumptions!B64*Assumptions!B10 -> 1028516.5
A23: Insurance | B23: =0 -> 0 | C23: =Assumptions!B65*Assumptions!B43 -> 243825 | D23: =Assumptions!B65*Assumptions!B43 -> 243825 | E23: =Assumptions!B65*Assumptions!B43 -> 243825 | F23: =Assumptions!B65*Assumptions!B43 -> 243825 | G23: =Assumptions!B65*Assumptions!B43 -> 243825 | H23: =Assumptions!B65*Assumptions!B43 -> 243825
A24: Operating Expenses | B24: =Assumptions!B32*Assumptions!D7 -> 154122.5 | C24: =Assumptions!B49*Assumptions!B46 -> 1462950 | D24: =Assumptions!B49*Assumptions!B46 -> 1462950 | E24: =Assumptions!B49*Assumptions!B46 -> 1462950 | F24: =Assumptions!B49*Assumptions!B46 -> 1462950 | G24: =Assumptions!B49*Assumptions!B46 -> 1462950 | H24: =Assumptions!B49*Assumptions!B46 -> 1462950
A25: Management Fee | B25: =Assumptions!B66*MAX(B19,0) -> 41905.32 | C25: =Assumptions!B66*MAX(C19,0) -> 167987.28 | D25: =Assumptions!B66*MAX(D19,0) -> 162236.28 | E25: =Assumptions!B66*MAX(E19,0) -> 167103.37 | F25: =Assumptions!B66*MAX(F19,0) -> 172116.47 | G25: =Assumptions!B66*MAX(G19,0) -> 177279.96 | H25: =Assumptions!B66*MAX(H19,0) -> 182598.36
A26: TOTAL OPERATING EXPENSES | B26: =SUM(B22:B25) -> 674384.82 | C26: =SUM(C22:C25) -> 2903278.8 | D26: =SUM(D22:D25) -> 2897527.8 | E26: =SUM(E22:E25) -> 2902394.9 | F26: =SUM(F22:F25) -> 2907408 | G26: =SUM(G22:G25) -> 2912571.5 | H26: =SUM(H22:H25) -> 2917889.9
A28: NET OPERATING INCOME
A29: NET OPERATING INCOME (NOI) | B29: =B19-B26 -> 373248.18 | C29: =C19-C26 -> 1296403.2 | D29: =D19-D26 -> 1158379.2 | E29: =E19-E26 -> 1275189.3 | F29: =F19-F26 -> 1395503.7 | G29: =G19-G26 -> 1519427.6 | H29: =H19-H26 -> 1647069.2
A31: DEBT SERVICE
A32: Annual Debt Service | B32: =Assumptions!D17 -> 1685970 | C32: =Assumptions!D17 -> 1685970 | D32: =Assumptions!D17 -> 1685970 | E32: =Assumptions!D17 -> 1685970 | F32: =Assumptions!D17 -> 1685970 | G32: =Assumptions!D17 -> 1685970 | H32: =Assumptions!D17 -> 1685970
A33: CASH FLOW AFTER DEBT SERVICE | B33: =B29-B32 -> -1312721.8 | C33: =C29-C32 -> -389566.78 | D33: =D29-D32 -> -527590.82 | E33: =E29-E32 -> -410780.7 | F33: =F29-F32 -> -290466.27 | G33: =G29-G32 -> -166542.41 | H33: =H29-H32 -> -38900.842
A35: EXIT ANALYSIS (Year 6 Sale)
A36: Stabilized NOI (Year 6) | I36: =H29 -> 1647069.2
A37: Exit Cap Rate | I37: =Assumptions!D46 -> 0.055
A38: Gross Sale Price | I38: =I36/I37 -> 29946712
A39: Selling Costs | I39: =-I38*Assumptions!B67 -> -598934.24
A40: Net Sale Proceeds | I40: =I38+I39 -> 29347778
A41: Less: Loan Payoff | I41: =-Assumptions!B16 -> -25938000
A42: NET EQUITY REVERSION | I42: =I40+I41 -> 3409777.7
A44: RETURN METRICS
A45: Total Cash Flow (incl. exit) | B45: =B33-B13 -> -36165847 | C45: =C33-C13 -> -942236.78 | D45: =D33-D13 -> -527590.82 | E45: =E33-E13 -> -410780.7 | F45: =F33-F13 -> -290466.27 | G45: =G33-G13 -> -166542.41 | H45: =H33-H13 -> -38900.842 | I45: =H33-H13+I42 -> 3370876.9
A46: Cumulative Cash Flow | B46: =B45 -> -36165847 | C46: =B46+C45 -> -37108084 | D46: =C46+D45 -> -37635674 | E46: =D46+E45 -> -38046455 | F46: =E46+F45 -> -38336921 | G46: =F46+G45 -> -38503464 | H46: =G46+H45 -> -38542365 | I46: =H46+I45 -> -35171488
A48: Total Development Cost | B48: =I13 -> 35405795
A49: Stabilized NOI (Year 6) | B49: =H29 -> 1647069.2
...

Sheet 3D Multifamily
A1: Scenario 3D: Multi-Family Residential
A2: 648 & 650 Grassmere Park Drive
B4: Year 0 2026 | C4: Year 1 2027 | D4: Year 2 2028 | E4: Year 3 2029 | F4: Year 4 2030 | G4: Year 5 2031 | H4: Year 6 2032 | I4: Total/Exit
A6: DEVELOPMENT COSTS
A7: Demolition + Site Prep | B7: =Assumptions!D24 -> 3940388
A8: Hard Construction Cost | B8: =Assumptions!B55 -> 72000000
A9: Soft Costs (% of hard costs) | B9: =(B7+B8)*Assumptions!B68 -> 11391058
A10: Contingency (% of hard costs) | B10: =(B7+B8)*Assumptions!B69 -> 7594038.8
A11: BZA / Entitlement Costs | B11: 150000
A12: Leasing Commissions (Year 1) | C12: 0
A13: TOTAL DEVELOPMENT COST | B13: =SUM(B7:B12) -> 95075485 | C13: =SUM(C7:C12) -> 0 | I13: =SUM(B13:H13) -> 95075485
A15: REVENUE
A16: Asurion Annex Rent (through Mar 2027) | B16: =Assumptions!D19 -> 1047633 | C16: =Assumptions!D19*0.25 -> 261908.25
A17: Residential Gross Potential Rent | E17: =Assumptions!D55*12*Assumptions!B53*0.5 -> 3960000 | F17: =E17*(1+Assumptions!B59) -> 4078800 | G17: =F17*(1+Assumptions!B59) -> 4201164 | H17: =G17*(1+Assumptions!B59) -> 4327198.9
A18: Vacancy Loss | E18: =-E17*(1-Assumptions!B56) -> -277200 | F18: =-F17*(1-Assumptions!B56) -> -285516 | G18: =-G17*(1-Assumptions!B56) -> -294081.48 | H18: =-H17*(1-Assumptions!B56) -> -302903.92 | I18: =-I17*(1-Assumptions!B56) -> 0
A19: EFFECTIVE GROSS INCOME | B19: =SUM(B16:B18) -> 1047633 | C19: =SUM(C16:C18) -> 261908.25 | D19: =SUM(D16:D18) -> 0 | E19: =SUM(E16:E18) -> 3682800 | F19: =SUM(F16:F18) -> 3793284 | G19: =SUM(G16:G18) -> 3907082.5 | H19: =SUM(H16:H18) -> 4024295 | I19: =SUM(I16:I18) -> 0
A21: OPERATING EXPENSES
A22: Property Taxes | B22: =Assumptions!B64*Assumptions!B11 -> 478357 | C22: =Assumptions!B64*Assumptions!B11 -> 478357 | D22: =Assumptions!B64*Assumptions!B11 -> 478357 | E22: =Assumptions!B64*Assumptions!B11 -> 478357 | F22: =Assumptions!B64*Assumptions!B10 -> 1028516.5 | G22: =Assumptions!B64*Assumptions!B10 -> 1028516.5 | H22: =Assumptions!B64*Assumptions!B10 -> 1028516.5
A23: Insurance | B23: =0 -> 0 | C23: =0 -> 0 | D23: =0 -> 0 | E23: =0 -> 0 | F23: =Assumptions!B65*Assumptions!B54 -> 540000 | G23: =Assumptions!B65*Assumptions!B54 -> 540000 | H23: =Assumptions!B65*Assumptions!B54 -> 540000
A24: Operating Expenses | B24: =Assumptions!B32*Assumptions!D7 -> 154122.5 | C24: =Assumptions!B32*Assumptions!D7 -> 154122.5 | D24: =0 -> 0 | E24: =0 -> 0 | F24: =Assumptions!D58*Assumptions!B53 -> 2400000 | G24: =Assumptions!D58*Assumptions!B53 -> 2400000 | H24: =Assumptions!D58*Assumptions!B53 -> 2400000
A25: Management Fee | B25: =Assumptions!B66*MAX(B19,0) -> 41905.32 | C25: =Assumptions!B66*MAX(C19,0) -> 10476.33 | D25: =Assumptions!B66*MAX(D19,0) -> 0 | E25: =Assumptions!B66*MAX(E19,0) -> 147312 | F25: =Assumptions!B66*MAX(F19,0) -> 151731.36 | G25: =Assumptions!B66*MAX(G19,0) -> 156283.3 | H25: =Assumptions!B66*MAX(H19,0) -> 160971.8
A26: TOTAL OPERATING EXPENSES | B26: =SUM(B22:B25) -> 674384.82 | C26: =SUM(C22:C25) -> 642955.83 | D26: =SUM(D22:D25) -> 478357 | E26: =SUM(E22:E25) -> 625669 | F26: =SUM(F22:F25) -> 4120247.9 | G26: =SUM(G22:G25) -> 4124799.8 | H26: =SUM(H22:H25) -> 4129488.3
A28: NET OPERATING INCOME
A29: NET OPERATING INCOME (NOI) | B29: =B19-B26 -> 373248.18 | C29: =C19-C26 -> -381047.58 | D29: =D19-D26 -> -478357 | E29: =E19-E26 -> 3057131 | F29: =F19-F26 -> -326963.86 | G29: =G19-G26 -> -217717.28 | H29: =H19-H26 -> -105193.3
A31: DEBT SERVICE
A32: Annual Debt Service | B32: =Assumptions!D17 -> 1685970 | C32: =Assumptions!D17 -> 1685970 | D32: =Assumptions!D17 -> 1685970 | E32: =Assumptions!D17 -> 1685970 | F32: =Assumptions!D17 -> 1685970 | G32: =Assumptions!D17 -> 1685970 | H32: =Assumptions!D17 -> 1685970
A33: CASH FLOW AFTER DEBT SERVICE | B33: =B29-B32 -> -1312721.8 | C33: =C29-C32 -> -2067017.6 | D33: =D29-D32 -> -2164327 | E33: =E29-E32 -> 1371161 | F33: =F29-F32 -> -2012933.9 | G33: =G29-G32 -> -1903687.3 | H33: =H29-H32 -> -1791163.3
A35: EXIT ANALYSIS (Year 6 Sale)
A36: Stabilized NOI (Year 6) | I36: =H29 -> -105193.3
A37: Exit Cap Rate | I37: =Assumptions!D56 -> 0.05
A38: Gross Sale Price | I38: =I36/I37 -> -2103866.1
A39: Selling Costs | I39: =-I38*Assumptions!B67 -> 42077.322
A40: Net Sale Proceeds | I40: =I38+I39 -> -2061788.8
A41: Less: Loan Payoff | I41: =-Assumptions!B16 -> -25938000
A42: NET EQUITY REVERSION | I42: =I40+I41 -> -27999789
A44: RETURN METRICS
A45: Total Cash Flow (incl. exit) | B45: =B33-B13 -> -96388207 | C45: =C33-C13 -> -2067017.6 | D45: =D33-D13 -> -2164327 | E45: =E33-E13 -> 1371161 | F45: =F33-F13 -> -2012933.9 | G45: =G33-G13 -> -1903687.3 | H45: =H33-H13 -> -1791163.3 | I45: =H33-H13+I42 -> -29790952
A46: Cumulative Cash Flow | B46: =B45 -> -96388207 | C46: =B46+C45 -> -98455224 | D46: =C46+D45 -> -1.0061955e+08 | E46: =D46+E45 -> -99248390 | F46: =E46+F45 -> -1.0126132e+08 | G46: =F46+G45 -> -1.0316501e+08 | H46: =G46+H45 -> -1.0495617e+08 | I46: =H46+I45 -> -1.3474713e+08
A48: Total Development Cost | B48: =I13 -> 95075485
A49: Stabilized NOI (Year 6) | B49: =H29 -> -105193.3
...
